Workbook

Sheet Product Hierarchy
A1: L5 SKU | B1: L5 Part # | C1: Brand | D1: DESCRIPTION | E1: Product Group | F1: Product Type
A2: DXTT-3-730 | B2: 3-730 | C2: DEWALT | D2: DEWALT 16 x 3 1/8" Mag Float | E2: Concrete Hand Tools | F2: Concrete Floats
A3: DXTT-3-731 | B3: 3-731 | C3: DEWALT | D3: DEWALT 15.5" x 3" Extruded Aluminum Float | E3: Concrete Hand Tools | F3: Concrete Floats
A4: 5-730 | B4: 5-730 | C4: LEVEL5 | D4: 15.5" x 3" Extruded Aluminum Float | E4: Concrete Hand Tools | F4: Concrete Floats
A5: 5-731 | B5: 5-731 | C5: LEVEL5 | D5: 16" x 3 1/8" Extruded Magnesium Float | E5: Concrete Hand Tools | F5: Concrete Floats
A6: 5-920 | B6: 5-920 | C6: LEVEL5 | D6: 9" x 4" Black Rubber Float; Composite Hndl | E6: Concrete Hand Tools | F6: Concrete Floats
A7: 5-921 | B7: 5-921 | C7: LEVEL5 | D7: 9" x 4" Red Rubber Float; Composite Hndl | E7: Concrete Hand Tools | F7: Concrete Floats
A8: 5-925 | B8: 5-925 | C8: LEVEL5 | D8: 6" x 2" Margin Float | E8: Concrete Hand Tools | F8: Concrete Floats
A9: DXTT-3-744 | B9: 3-744 | C9: DEWALT | D9: DEWALT 6" x 3" Stainless Steel Edger | E9: Concrete Hand Tools | F9: Edgers
A10: DXTT-3-745 | B10: 3-745 | C10: DEWALT | D10: DEWALT 6 x 4" SS Edger | E10: Concrete Hand Tools | F10: Edgers
A11: 5-740 | B11: 5-740 | C11: LEVEL5 | D11: 10" x 10" x 1/2" Walking Edger | E11: Concrete Hand Tools | F11: Edgers
A12: 5-743 | B12: 5-743 | C12: LEVEL5 | D12: 6" x 3" Concrete Edger | E12: Concrete Hand Tools | F12: Edgers
... A466: 4-748 | B466: 4-748 | C466: LEVEL5 | D466: 90° Outside Corner Applicator Head | E466: Drywall Auto Tools | F466: Outside Applicator Head
A467: 1142 | B467: 1142 | C467: DEWALT | D467: MudShot Nozzle Assembly | E467: Drywall Auto Tools | F467: Parts
A468: 1143 | B468: 1143 | C468: DEWALT | D468: DEWALT Double Threaded Mudshot Connector | E468: Drywall Auto Tools | F468: Parts
A469: 2166 | B469: 2166 | C469: DEWALT | D469: DEWALT Taper Tube | E469: Drywall Auto Tools | F469: Parts
A470: 2212 | B470: 2212 | C470: DEWALT | D470: DeWalt Ext Box Handle Head | E470: Drywall Auto Tools | F470: Parts
A471: 2-774R | B471: 2-774R | C471: DEWALT | D471: REFURB DEWALT MS Pressurized Applicator Tube | E471: Drywall Auto Tools | F471: Parts
A472: 9191DW | B472: 9191DW | C472: DEWALT | D472: Wrench -DeWalt Customer MCM-7122A14 | E472: Drywall Auto Tools | F472: Parts
A473: DXTT-1101 | B473: 1101 | C473: DEWALT | D473: Extension O'Ring | E473: Drywall Auto Tools | F473: Parts
A474: DXTT-1102 | B474: 1102 | C474: DEWALT | D474: Screw 8-32 x 6 | E474: Drywall Auto Tools | F474: Parts
A475: DXTT-1103 | B475: 1103 | C475: DEWALT | D475: Screw 8-32 x 9.4 | E475: Drywall Auto Tools | F475: Parts
A476: DXTT-1104 | B476: 1104 | C476: DEWALT | D476: Threaded Extension End | E476: Drywall Auto Tools | F476: Parts
A477: DXTT-1105 | B477: 1105 | C477: DEWALT | D477: Rubber Handle Grip | E477: Drywall Auto Tools | F477: Parts
A478: DXTT-1107 | B478: 1107 | C478: DEWALT | D478: Screw 6-32 x 7 | E478: Drywall Auto Tools | F478: Parts
A479: DXTT-1108 | B479: 1108 | C479: DEWALT | D479: Base | E479: Drywall Auto Tools | F479: Parts
A480: DXTT-1109 | B480: 1109 | C480: DEWALT | D480: MudShot U-Cup | E480: Drywall Auto Tools | F480: Parts
A481: DXTT-1110 | B481: 1110 | C481: DEWALT | D481: Screw 6-32 x 10.7 | E481: Drywall Auto Tools | F481: Parts
A482: DXTT-1111 | B482: 1111 | C482: DEWALT | D482: Clear Tube Base | E482: Drywall Auto Tools | F482: Parts
A483: DXTT-1112 | B483: 1112 | C483: DEWALT | D483: Top/Bottom Support Band | E483: Drywall Auto Tools | F483: Parts
A484: DXTT-1113 | B484: 1113 | C484: DEWALT | D484: Clear Tube | E484: Drywall Auto Tools | F484: Parts
... A531: DXTT-2719 | B531: 2719 | C531: DEWALT | D531: Black Box Wheel | E531: Drywall Auto Tools | F531: Parts
A532: DXTT-2-774 | B532: 2-774 | C532: DEWALT | D532: DEWALT MS Pressurized Applicator Tube | E532: Drywall Auto Tools | F532: Parts
A533: DXTT-2-801 | B533: 2-801 | C533: DEWALT | D533: DEWALT Pump Rebuild Kit | E533: Drywall Auto Tools | F533: Repair Kits
A534: DXTT-2-805 | B534: 2-805 | C534: DEWALT | D534: DEWALT 7"Flat Box Seal | E534: Drywall Auto Tools | F534: Parts
A535: DXTT-2-806 | B535: 2-806 | C535: DEWALT | D535: DEWALT 10"Flat Box Seal | E535: Drywall Auto Tools | F535: Parts
A536: DXTT-2-807 | B536: 2-807 | C536: DEWALT | D536: DEWALT 12"Flat Box Seal | E536: Drywall Auto Tools | F536: Parts
A537: DXTT-9685 | B537: 9685 | C537: DEWALT | D537: FB Box Tire | E537: Drywall Auto Tools | F537: Parts
A538: 1137 | B538: 1137 | C538: LEVEL5 | D538: MR Gas Cylinder | E538: Drywall Auto Tools | F538: Parts
A539: 7001 | B539: 7001 | C539: LEVEL5 | D539: Handle Outlet Valve | E539: Drywall Auto Tools | F539: Parts
...

Sheet Order Summary
D1: Tier 1 Order Form Summary
A3: Customer: | E3: Order date:
A4: Ship To: | E4: PO#:
E5: Need by date:
E6: Carrier:
E11: Order Quantity | F11: Total Price
A12: Level5 | B12: Drywall Hand Tools | E12: =SUMIFS('Order Input - Level5'!L:L,'Order Input - Level5'!C:C,'Order Summary'!A12,'Order Input - Level5'!D:D,'Order Summary'!B12) -> 0 | F12: =SUMIFS('Order Input - Level5'!M:M,'Order Input - Level5'!C:C,'Order Summary'!A12,'Order Input - Level5'!D:D,'Order Summary'!B12) -> 0
A13: Level5 | B13: Drywall Semi Auto Tools | E13: =SUMIFS('Order Input - Level5'!L:L,'Order Input - Level5'!C:C,'Order Summary'!A13,'Order Input - Level5'!D:D,'Order Summary'!B13) -> 0 | F13: =SUMIFS('Order Input - Level5'!M:M,'Order Input - Level5'!C:C,'Order Summary'!A13,'Order Input - Level5'!D:D,'Order Summary'!B13) -> 0
A14: Level5 | B14: Drywall Auto Tools | E14: =SUMIFS('Order Input - Level5'!L:L,'Order Input - Level5'!C:C,'Order Summary'!A14,'Order Input - Level5'!D:D,'Order Summary'!B14) -> 0 | F14: =SUMIFS('Order Input - Level5'!M:M,'Order Input - Level5'!C:C,'Order Summary'!A14,'Order Input - Level5'!D:D,'Order Summary'!B14) -> 0
A15: DeWalt | B15: Drywall Hand Tools | E15: =SUMIFS('Order Input - DeWalt'!L:L,'Order Input - DeWalt'!C:C,'Order Summary'!A15,'Order Input - DeWalt'!D:D,'Order Summary'!B15) -> 0 | F15: =SUMIFS('Order Input - DeWalt'!M:M,'Order Input - DeWalt'!C:C,'Order Summary'!A15,'Order Input - DeWalt'!D:D,'Order Summary'!B15) -> 0
A16: DeWalt | B16: Concrete Hand Tools | E16: =SUMIFS('Order Input - DeWalt'!L:L,'Order Input - DeWalt'!C:C,'Order Summary'!A16,'Order Input - DeWalt'!D:D,'Order Summary'!B16) -> 0 | F16: =SUMIFS('Order Input - DeWalt'!M:M,'Order Input - DeWalt'!C:C,'Order Summary'!A16,'Order Input - DeWalt'!D:D,'Order Summary'!B16) -> 0
A17: DeWalt | B17: Drywall Semi Auto Tools | E17: =SUMIFS('Order Input - DeWalt'!L:L,'Order Input - DeWalt'!C:C,'Order Summary'!A17,'Order Input - DeWalt'!D:D,'Order Summary'!B17) -> 0 | F17: =SUMIFS('Order Input - DeWalt'!M:M,'Order Input - DeWalt'!C:C,'Order Summary'!A17,'Order Input - DeWalt'!D:D,'Order Summary'!B17) -> 0
A18: DeWalt | B18: Drywall Auto Tools | E18: =SUMIFS('Order Input - DeWalt'!L:L,'Order Input - DeWalt'!C:C,'Order Summary'!A18,'Order Input - DeWalt'!D:D,'Order Summary'!B18) -> 0 | F18: =SUMIFS('Order Input - DeWalt'!M:M,'Order Input - DeWalt'!C:C,'Order Summary'!A18,'Order Input - DeWalt'!D:D,'Order Summary'!B18) -> 0
B19: Individual Parts totals: | E19: ='Order Input-Individual Part '!K133 -> 0 | F19: ='Order Input-Individual Part '!L133 -> 0
B20: Part Kits totals: | E20: ='Order Input-Part Kits'!K74 -> 0 | F20: ='Order Input-Part Kits'!L74 -> 0
B21: Merch. And Marketing: | E21: ='Order Input-Merch. And Mktg'!K25 -> 0 | F21: ='Order Input-Merch. And Mktg'!L25 -> 0
B22: Order totals: | E22: =SUM(E12:E21) -> 0 | F22: =SUM(F12:F21) -> 0
A29: Ordering instructions:
A30: 1) Please enter order details (Customer name, Ship to address, PO#, etc.) on the top of this tab, the other tabs will populate
A31: 2) Enter the quantities you would like to order on the appropriate line item in the Order Input tabs and
A32: the Order Summary page will calculate your order totals.
A33: Please contact us at orders@level5tools.com if you have questions.

Sheet Order Input - Level5
H1: Order Form
A3: Customer: | C3: ='Order Summary'!B3 -> 0 | J3: Order date: | N3: ='Order Summary'!$F3 -> 0
A4: Ship To: | C4: ='Order Summary'!B4 -> 0 | J4: PO#: | N4: ='Order Summary'!$F4 -> 0
A5: ='Order Summary'!B5 -> 0 | J5: Need by date: | N5: ='Order Summary'!$F5 -> 0
A6: ='Order Summary'!B6 -> 0 | J6: Carrier: | N6: ='Order Summary'!$F6 -> 0
A7: Please note that the case quantities are noted for each Product. Ordering in multiples of inner case quantities helps us keep costs low to you and reduces damage during shipping.
A10: Part # | B10: Sku # | C10: Description | D10: Brand | E10: Product Group | F10: Product Type | G10: MSRP | H10: MAPP | I10: Your Price | J10: UOM | K10: Inner Case Qty | L10: Master Case Qty | M10: Order Quantity | N10: Total Price
A11: 449324 | B11: 4-001 | C11: 4" Mud Roller | D11: =_xlfn.XLOOKUP(B11,'Product Hierarchy'!A:A,'Product Hierarchy'!C:C) -> LEVEL5 | E11: =_xlfn.XLOOKUP(B11,'Product Hierarchy'!A:A,'Product Hierarchy'!E:E) -> Drywall Hand Tools | F11: =_xlfn.XLOOKUP(B11,'Product Hierarchy'!A:A,'Product Hierarchy'!F:F) -> Rollers | G11: 18.49 | H11: 16.64 | I11: 11.65 | J11: Each | K11: 12 | L11: 48 | N11: =M11*I11 -> 0
A12: 449325 | B12: 4-002 | C12: Corner Mud Roller | D12: =_xlfn.XLOOKUP(B12,'Product Hierarchy'!A:A,'Product Hierarchy'!C:C) -> LEVEL5 | E12: =_xlfn.XLOOKUP(B12,'Product Hierarchy'!A:A,'Product Hierarchy'!E:E) -> Drywall Hand Tools | F12: =_xlfn.XLOOKUP(B12,'Product Hierarchy'!A:A,'Product Hierarchy'!F:F) -> Rollers | G12: 21.99 | H12: 19.79 | I12: 13.85 | J12: Each | K12: 6 | L12: 24 | N12: =M12*I12 -> 0
A13: 449326 | B13: 4-003 | C13: 4" Mud Roller Frame | D13: =_xlfn.XLOOKUP(B13,'Product Hierarchy'!A:A,'Product Hierarchy'!C:C) -> LEVEL5 | E13: =_xlfn.XLOOKUP(B13,'Product Hierarchy'!A:A,'Product Hierarchy'!E:E) -> Drywall Hand Tools | F13: =_xlfn.XLOOKUP(B13,'Product Hierarchy'!A:A,'Product Hierarchy'!F:F) -> Rollers | G13: 12.99 | H13: 11.69 | I13: 8.18 | J13: Each | K13: 6 | L13: 24 | N13: =M13*I13 -> 0
A14: 449327 | B14: 4-004 | C14: Corner Mud Roller Frame | D14: =_xlfn.XLOOKUP(B14,'Product Hierarchy'!A:A,'Product Hierarchy'!C:C) -> LEVEL5 | E14: =_xlfn.XLOOKUP(B14,'Product Hierarchy'!A:A,'Product Hierarchy'!E:E) -> Drywall Hand Tools | F14: =_xlfn.XLOOKUP(B14,'Product Hierarchy'!A:A,'Product Hierarchy'!F:F) -> Rollers | G14: 12.99 | H14: 11.69 | I14: 8.18 | J14: Each | K14: 6 | L14: 24 | N14: =M14*I14 -> 0
A15: 449328 | B15: 4-005 | C15: 4" Mud Roller w/Frame | D15: =_xlfn.XLOOKUP(B15,'Product Hierarchy'!A:A,'Product Hierarchy'!C:C) -> LEVEL5 | E15: =_xlfn.XLOOKUP(B15,'Product Hierarchy'!A:A,'Product Hierarchy'!E:E) -> Drywall Hand Tools | F15: =_xlfn.XLOOKUP(B15,'Product Hierarchy'!A:A,'Product Hierarchy'!F:F) -> Rollers | G15: 31.48 | H15: 28.33 | I15: 19.83 | J15: Each | K15: 6 | L15: 24 | N15: =M15*I15 -> 0
A16: 449329 | B16: 4-006 | C16: Corner Mud Roller w/Frame | D16: =_xlfn.XLOOKUP(B16,'Product Hierarchy'!A:A,'Product Hierarchy'!C:C) -> LEVEL5 | E16: =_xlfn.XLOOKUP(B16,'Product Hierarchy'!A:A,'Product Hierarchy'!E:E) -> Drywall Hand Tools | F16: =_xlfn.XLOOKUP(B16,'Product Hierarchy'!A:A,'Product Hierarchy'!F:F) -> Rollers | G16: 34.98 | H16: 31.48 | I16: 22.04 | J16: Each | K16: 6 | L16: 24 | N16: =M16*I16 -> 0
A17: 449330 | B17: 4-007 | C17: 4" Mud Roller Cover 3pk | D17: =_xlfn.XLOOKUP(B17,'Product Hierarchy'!A:A,'Product Hierarchy'!C:C) -> LEVEL5 | E17: =_xlfn.XLOOKUP(B17,'Product Hierarchy'!A:A,'Product Hierarchy'!E:E) -> Drywall Hand Tools | F17: =_xlfn.XLOOKUP(B17,'Product Hierarchy'!A:A,'Product Hierarchy'!F:F) -> Rollers | G17: 55.47 | H17: 49.92 | I17: 34.94 | J17: Each | K17: 1 | L17: 1 | N17: =M17*I17 -> 0
A18: 449331 | B18: 4-008 | C18: Corner Mud Roller Cover 3pk | D18: =_xlfn.XLOOKUP(B18,'Product Hierarchy'!A:A,'Product Hierarchy'!C:C) -> LEVEL5 | E18: =_xlfn.XLOOKUP(B18,'Product Hierarchy'!A:A,'Product Hierarchy'!E:E) -> Drywall Hand Tools | F18: =_xlfn.XLOOKUP(B18,'Product Hierarchy'!A:A,'Product Hierarchy'!F:F) -> Rollers | G18: 65.97 | H18: 59.37 | I18: 41.56 | J18: Each | K18: 1 | L18: 1 | N18: =M18*I18 -> 0
A19: 449332 | B19: 4-009 | C19: 9"Mud Roller-3pk | D19: =_xlfn.XLOOKUP(B19,'Product Hierarchy'!A:A,'Product Hierarchy'!C:C) -> LEVEL5 | E19: =_xlfn.XLOOKUP(B19,'Product Hierarchy'!A:A,'Product Hierarchy'!E:E) -> Drywall Hand Tools | F19: =_xlfn.XLOOKUP(B19,'Product Hierarchy'!A:A,'Product Hierarchy'!F:F) -> Rollers | G19: 62.97 | H19: 56.67 | I19: 39.67 | J19: Each | K19: 1 | L19: 1 | N19: =M19*I19 -> 0
A20: 449333 | B20: 4-012 | C20: 12"Mud Roller-3pk | D20: =_xlfn.XLOOKUP(B20,'Product Hierarchy'!A:A,'Product Hierarchy'!C:C) -> LEVEL5 | E20: =_xlfn.XLOOKUP(B20,'Product Hierarchy'!A:A,'Product Hierarchy'!E:E) -> Drywall Hand Tools | F20: =_xlfn.XLOOKUP(B20,'Product Hierarchy'!A:A,'Product Hierarchy'!F:F) -> Rollers | G20: 68.97 | H20: 62.07 | I20: 43.45 | J20: Each | K20: 1 | L20: 1 | N20: =M20*I20 -> 0
A21: 449384 | B21: 4-600P | C21: Taping Finishing Set w/Fixed Hndls-P | D21: =_xlfn.XLOOKUP(B21,'Product Hierarchy'!A:A,'Product Hierarchy'!C:C) -> LEVEL5 | E21: =_xlfn.XLOOKUP(B21,'Product Hierarchy'!A:A,'Product Hierarchy'!E:E) -> Drywall Auto Tools | F21: =_xlfn.XLOOKUP(B21,'Product Hierarchy'!A:A,'Product Hierarchy'!F:F) -> Auto Tool Sets | G21: 4813.38 | H21: 3850.7 | I21: 2695.49 | J21: Each | K21: 1 | L21: 1 | N21: =M21*I21 -> 0
A22: 449386 | B22: 4-601P | C22: Taping Finishing Set w/Ext Hndls-P | D22: =_xlfn.XLOOKUP(B22,'Product Hierarchy'!A:A,'Product Hierarchy'!C:C) -> LEVEL5 | E22: =_xlfn.XLOOKUP(B22,'Product Hierarchy'!A:A,'Product Hierarchy'!E:E) -> Drywall Auto Tools | F22: =_xlfn.XLOOKUP(B22,'Product Hierarchy'!A:A,'Product Hierarchy'!F:F) -> Auto Tool Sets | G22: 5265.85 | H22: 4212.68 | I22: 2948.88 | J22: Each | K22: 1 | L22: 1 | N22: =M22*I22 -> 0
... A47: 449488 | B47: 4-735 | C47: 4"Corner Finisher | D47: =_xlfn.XLOOKUP(B47,'Product Hierarchy'!A:A,'Product Hierarchy'!C:C) -> LEVEL5 | E47: =_xlfn.XLOOKUP(B47,'Product Hierarchy'!A:A,'Product Hierarchy'!E:E) -> Drywall Auto Tools | F47: =_xlfn.XLOOKUP(B47,'Product Hierarchy'!A:A,'Product Hierarchy'!F:F) -> Corner Finishers | G47: 500.49 | H47: 425.42 | I47: 297.79 | J47: Each | K47: 1 | L47: 10 | N47: =M47*I47 -> 0
A48: 450989 | B48: 4-735CASE-B | C48: 4" Corner Finisher Case w/Foam Insert (No Tool) | D48: LEVEL5 | E48: Drywall Auto Tools | F48: Storage | G48: 53.49 | H48: 45.47 | I48: 31.83 | J48: Each | K48: 1 | L48: 10 | N48: =M48*I48 -> 0
A49: 449491 | B49: 4-740 | C49: 54"Fixed Flat Box Hndl | D49: =_xlfn.XLOOKUP(B49,'Product Hierarchy'!A:A,'Product Hierarchy'!C:C) -> LEVEL5 | E49: =_xlfn.XLOOKUP(B49,'Product Hierarchy'!A:A,'Product Hierarchy'!E:E) -> Drywall Auto Tools | F49: =_xlfn.XLOOKUP(B49,'Product Hierarchy'!A:A,'Product Hierarchy'!F:F) -> Handles | G49: 238.49 | H49: 202.72 | I49: 141.9 | J49: Each | K49: 6 | L49: 6 | N49: =M49*I49 -> 0
A50: 449493 | B50: 4-741 | C50: Comound Tube 42" | D50: =_xlfn.XLOOKUP(B50,'Product Hierarchy'!A:A,'Product Hierarchy'!C:C) -> LEVEL5 | E50: =_xlfn.XLOOKUP(B50,'Product Hierarchy'!A:A,'Product Hierarchy'!E:E) -> Drywall Semi Auto Tools | F50: =_xlfn.XLOOKUP(B50,'Product Hierarchy'!A:A,'Product Hierarchy'!F:F) -> Compound Dispensers | G50: 226.49 | H50: 203.84 | I50: 142.69 | J50: Each | K50: 1 | L50: 4 | N50: =M50*I50 -> 0
A51: 449495 | B51: 4-743 | C51: 3"Direct Corner Flusher w/Wheels | D51: =_xlfn.XLOOKUP(B51,'Product Hierarchy'!A:A,'Product Hierarchy'!C:C) -> LEVEL5 | E51: =_xlfn.XLOOKUP(B51,'Product Hierarchy'!A:A,'Product Hierarchy'!E:E) -> Drywall Semi Auto Tools | F51: =_xlfn.XLOOKUP(B51,'Product Hierarchy'!A:A,'Product Hierarchy'!F:F) -> Flushers | G51: 142.99 | H51: 128.69 | I51: 90.08 | J51: Each | K51: 1 | L51: 12 | N51: =M51*I51 -> 0
A52: 449496 | B52: 4-744 | C52: 3.5"Direct Corner Flusher w/Wheels | D52: =_xlfn.XLOOKUP(B52,'Product Hierarchy'!A:A,'Product Hierarchy'!C:C) -> LEVEL5 | E52: =_xlfn.XLOOKUP(B52,'Product Hierarchy'!A:A,'Product Hierarchy'!E:E) -> Drywall Semi Auto Tools | F52: =_xlfn.XLOOKUP(B52,'Product Hierarchy'!A:A,'Product Hierarchy'!F:F) -> Flushers | G52: 147.49 | H52: 132.74 | I52: 92.92 | J52: Each | K52: 1 | L52: 12 | N52: =M52*I52 -> 0
A53: 450718 | B53: 4-746 | C53: Outside Corner Bead Mud Applicator | D53: =_xlfn.XLOOKUP(B53,'Product Hierarchy'!A:A,'Product Hierarchy'!C:C) -> LEVEL5 | E53: =_xlfn.XLOOKUP(B53,'Product Hierarchy'!A:A,'Product Hierarchy'!E:E) -> Drywall Auto Tools | F53: =_xlfn.XLOOKUP(B53,'Product Hierarchy'!A:A,'Product Hierarchy'!F:F) -> Outside Applicator Head | G53: 86.99 | H53: 73.94 | I53: 51.76 | J53: Each | K53: 1 | L53: 12 | N53: =M53*I53 -> 0
A54: 449500 | B54: 4-749 | C54: CT Box Filler Attachment | D54: =_xlfn.XLOOKUP(B54,'Product Hierarchy'!A:A,'Product Hierarchy'!C:C) -> LEVEL5 | E54: =_xlfn.XLOOKUP(B54,'Product Hierarchy'!A:A,'Product Hierarchy'!E:E) -> Drywall Auto Tools | F54: =_xlfn.XLOOKUP(B54,'Product Hierarchy'!A:A,'Product Hierarchy'!F:F) -> Compound Dispensers | G54: 31.99 | H54: 27.19 | I54: 19.03 | J54: Each | K54: 1 | L54: 12 | N54: =M54*I54 -> 0
A55: 449501 | B55: 4-754 | C55: 2"Nail Spotter (2G) | D55: =_xlfn.XLOOKUP(B55,'Product Hierarchy'!A:A,'Product Hierarchy'!C:C) -> LEVEL5 | E55: =_xlfn.XLOOKUP(B55,'Product Hierarchy'!A:A,'Product Hierarchy'!E:E) -> Drywall Auto Tools | F55: =_xlfn.XLOOKUP(B55,'Product Hierarchy'!A:A,'Product Hierarchy'!F:F) -> Nail Spotters | G55: 318.99 | H55: 271.14 | I55: 189.8 | J55: Each | K55: 1 | L55: 10 | N55: =M55*I55 -> 0
A56: 450990 | B56: 4-754CASE-B | C56: 2" Nail Spotter Case w/Foam Insert (No Tool) | D56: =_xlfn.XLOOKUP(B56,'Product Hierarchy'!A:A,'Product Hierarchy'!C:C) -> LEVEL5 | E56: =_xlfn.XLOOKUP(B56,'Product Hierarchy'!A:A,'Product Hierarchy'!E:E) -> Drywall Auto Tools | F56: =_xlfn.XLOOKUP(B56,'Product Hierarchy'!A:A,'Product Hierarchy'!F:F) -> Storage | G56: 53.49 | H56: 45.47 | I56: 31.83 | J56: Each | K56: 1 | L56: 10 | N56: =M56*I56 -> 0
A57: 449505 | B57: 4-755 | C57: 3"Nail Spotter (2G) | D57: =_xlfn.XLOOKUP(B57,'Product Hierarchy'!A:A,'Product Hierarchy'!C:C) -> LEVEL5 | E57: =_xlfn.XLOOKUP(B57,'Product Hierarchy'!A:A,'Product Hierarchy'!E:E) -> Drywall Auto Tools | F57: =_xlfn.XLOOKUP(B57,'Product Hierarchy'!A:A,'Product Hierarchy'!F:F) -> Nail Spotters | G57: 340.99 | H57: 289.84 | I57: 202.89 | J57: Each | K57: 1 | L57: 10 | N57: =M57*I57 -> 0
A58: 450991 | B58: 4-755CASE-B | C58: 3" Nail Spotter Case w/Foam Insert (No Tool) | D58: =_xlfn.XLOOKUP(B58,'Product Hierarchy'!A:A,'Product Hierarchy'!C:C) -> LEVEL5 | E58: =_xlfn.XLOOKUP(B58,'Product Hierarchy'!A:A,'Product Hierarchy'!E:E) -> Drywall Auto Tools | F58: =_xlfn.XLOOKUP(B58,'Product Hierarchy'!A:A,'Product Hierarchy'!F:F) -> Storage | G58: 53.49 | H58: 45.47 | I58: 31.83 | J58: Each | K58: 1 | L58: 10 | N58: =M58*I58 -> 0
A59: 449515 | B59: 4-759 | C59: 48"- 78"Flat Box Ext Hndl | D59: =_xlfn.XLOOKUP(B59,'Product Hierarchy'!A:A,'Product Hierarchy'!C:C) -> LEVEL5 | E59: =_xlfn.XLOOKUP(B59,'Product Hierarchy'!A:A,'Product Hierarchy'!E:E) -> Drywall Auto Tools | F59: =_xlfn.XLOOKUP(B59,'Product Hierarchy'!A:A,'Product Hierarchy'!F:F) -> Handles | G59: 368.49 | H59: 313.22 | I59: 219.25 | J59: Each | K59: 6 | L59: 6 | N59: =M59*I59 -> 0
A60: 449517 | B60: 4-760 | C60: Automatic Drywall Taper (2G) | D60: =_xlfn.XLOOKUP(B60,'Product Hierarchy'!A:A,'Product Hierarchy'!C:C) -> LEVEL5 | E60: =_xlfn.XLOOKUP(B60,'Product Hierarchy'!A:A,'Product Hierarchy'!E:E) -> Drywall Auto Tools | F60: =_xlfn.XLOOKUP(B60,'Product Hierarchy'!A:A,'Product Hierarchy'!F:F) -> Auto Tapers | G60: 1699.99 | H60: 1444.99 | I60: 1011.49 | J60: Each | K60: 1 | L60: 4 | N60: =M60*I60 -> 0
... A202: 449767 | B202: 5-311 | C202: Banjo | D202: =_xlfn.XLOOKUP(B202,'Product Hierarchy'!A:A,'Product Hierarchy'!C:C) -> LEVEL5 | E202: =_xlfn.XLOOKUP(B202,'Product Hierarchy'!A:A,'Product Hierarchy'!E:E) -> Drywall Semi Auto Tools | F202: =_xlfn.XLOOKUP(B202,'Product Hierarchy'!A:A,'Product Hierarchy'!F:F) -> Banjos | G202: 166.99 | H202: 150.29 | I202: 105.2 | J202: Each | K202: 1 | L202: 6 | N202: =M202*I202 -> 0
A203: 451003 | B203: 5-311CASE-H | C203: Banjo Case W/Foam Insert (NO TOOL) | D203: LEVEL5 | E203: Drywall Semi Auto Tools | F203: Storage | G203: 59.99 | H203: 53.99 | I203: 37.79 | J203: Each | K203: 1 | L203: 8 | N203: =M203*I203 -> 0
A204: 449769 | B204: 5-312 | C204: 6.5"x11.5"SS Corner Trowel-Sft Grp | D204: =_xlfn.XLOOKUP(B204,'Product Hierarchy'!A:A,'Product Hierarchy'!C:C) -> LEVEL5 | E204: =_xlfn.XLOOKUP(B204,'Product Hierarchy'!A:A,'Product Hierarchy'!E:E) -> Drywall Hand Tools | F204: =_xlfn.XLOOKUP(B204,'Product Hierarchy'!A:A,'Product Hierarchy'!F:F) -> Inside Corner Trowels | G204: 16.49 | H204: 14.84 | I204: 10.39 | J204: Each | K204: 6 | L204: 36 | N204: =M204*I204 -> 0
A205: 449770 | B205: 5-320 | C205: 4"x3.5"SS Corner Trowel-Sft Grp | D205: =_xlfn.XLOOKUP(B205,'Product Hierarchy'!A:A,'Product Hierarchy'!C:C) -> LEVEL5 | E205: =_xlfn.XLOOKUP(B205,'Product Hierarchy'!A:A,'Product Hierarchy'!E:E) -> Drywall Hand Tools | F205: =_xlfn.XLOOKUP(B205,'Product Hierarchy'!A:A,'Product Hierarchy'!F:F) -> Outside Corner Trowels | G205: 14.49 | H205: 13.04 | I205: 9.13 | J205: Each | K205: 6 | L205: 36 | N205: =M205*I205 -> 0
A206: 449771 | B206: 5-325 | C206: Hawk 13" x 13" | D206: =_xlfn.XLOOKUP(B206,'Product Hierarchy'!A:A,'Product Hierarchy'!C:C) -> LEVEL5 | E206: =_xlfn.XLOOKUP(B206,'Product Hierarchy'!A:A,'Product Hierarchy'!E:E) -> Drywall Hand Tools | F206: =_xlfn.XLOOKUP(B206,'Product Hierarchy'!A:A,'Product Hierarchy'!F:F) -> Hawks | G206: 49.99 | H206: 44.99 | I206: 31.49 | J206: Each | K206: 4 | L206: 4 | N206: =M206*I206 -> 0
A207: 449773 | B207: 5-326 | C207: Hawk 16" x 16" | D207: =_xlfn.XLOOKUP(B207,'Product Hierarchy'!A:A,'Product Hierarchy'!C:C) -> LEVEL5 | E207: =_xlfn.XLOOKUP(B207,'Product Hierarchy'!A:A,'Product Hierarchy'!E:E) -> Drywall Hand Tools | F207: =_xlfn.XLOOKUP(B207,'Product Hierarchy'!A:A,'Product Hierarchy'!F:F) -> Hawks | G207: 60.49 | H207: 54.44 | I207: 38.11 | J207: Each | K207: 1 | L207: 4 | N207: =M207*I207 -> 0
A208: 449775 | B208: 5-332 | C208: 12"SS Mud Pan | D208: =_xlfn.XLOOKUP(B208,'Product Hierarchy'!A:A,'Product Hierarchy'!C:C) -> LEVEL5 | E208: =_xlfn.XLOOKUP(B208,'Product Hierarchy'!A:A,'Product Hierarchy'!E:E) -> Drywall Hand Tools | F208: =_xlfn.XLOOKUP(B208,'Product Hierarchy'!A:A,'Product Hierarchy'!F:F) -> Mud Pans | G208: 23.99 | H208: 21.59 | I208: 15.11 | J208: Each | K208: 6 | L208: 12 | N208: =M208*I208 -> 0
...

Sheet Order Input - DeWalt
H1: Order Form
A3: Customer: | C3: ='Order Summary'!B3 -> 0 | J3: Order date: | N3: ='Order Summary'!$F3 -> 0
A4: Ship To: | C4: ='Order Summary'!B4 -> 0 | J4: PO#: | N4: ='Order Summary'!$F4 -> 0
A5: ='Order Summary'!B5 -> 0 | J5: Need by date: | N5: ='Order Summary'!$F5 -> 0
A6: ='Order Summary'!B6 -> 0 | J6: Carrier: | N6: ='Order Summary'!$F6 -> 0
A7: Please note that the case quantities are noted for each Product. Ordering in multiples of inner case quantities helps us keep costs low to you and reduces damage during shipping.
A10: Part # | B10: Sku # | C10: Description | D10: Brand | E10: Product Group | F10: Product Type | G10: MSRP | H10: MAPP | I10: Your Price | J10: UOM | K10: Inner Case Qty | L10: Master Case Qty | M10: Order Quantity | N10: Total Price
A11: 450016 | B11: DXTT-2-122 | C11: DEWALT 6"BS Taping Knife-Sft Grp Hndl | D11: =_xlfn.XLOOKUP(B11,'Product Hierarchy'!A:A,'Product Hierarchy'!C:C) -> DEWALT | E11: =_xlfn.XLOOKUP(B11,'Product Hierarchy'!A:A,'Product Hierarchy'!E:E) -> Drywall Hand Tools | F11: =_xlfn.XLOOKUP(B11,'Product Hierarchy'!A:A,'Product Hierarchy'!F:F) -> Taping Knives | G11: 17.49 | H11: 15.74 | I11: 11.02 | J11: Each | K11: 4 | L11: 24 | N11: =M11*I11 -> 0
A12: 450017 | B12: DXTT-2-124 | C12: DEWALT 8"BS Taping Knife-Sft Grp Hndl | D12: =_xlfn.XLOOKUP(B12,'Product Hierarchy'!A:A,'Product Hierarchy'!C:C) -> DEWALT | E12: =_xlfn.XLOOKUP(B12,'Product Hierarchy'!A:A,'Product Hierarchy'!E:E) -> Drywall Hand Tools | F12: =_xlfn.XLOOKUP(B12,'Product Hierarchy'!A:A,'Product Hierarchy'!F:F) -> Taping Knives | G12: 18.49 | H12: 16.64 | I12: 11.65 | J12: Each | K12: 4 | L12: 24 | N12: =M12*I12 -> 0
A13: 450018 | B13: DXTT-2-126 | C13: DEWALT 10"BS Taping Knife-Sft Grp Hndl | D13: =_xlfn.XLOOKUP(B13,'Product Hierarchy'!A:A,'Product Hierarchy'!C:C) -> DEWALT | E13: =_xlfn.XLOOKUP(B13,'Product Hierarchy'!A:A,'Product Hierarchy'!E:E) -> Drywall Hand Tools | F13: =_xlfn.XLOOKUP(B13,'Product Hierarchy'!A:A,'Product Hierarchy'!F:F) -> Taping Knives | G13: 19.49 | H13: 17.54 | I13: 12.28 | J13: Each | K13: 4 | L13: 24 | N13: =M13*I13 -> 0
A14: 450019 | B14: DXTT-2-127 | C14: DEWALT 12"BS Taping Knife-Sft Grp Hndl | D14: =_xlfn.XLOOKUP(B14,'Product Hierarchy'!A:A,'Product Hierarchy'!C:C) -> DEWALT | E14: =_xlfn.XLOOKUP(B14,'Product Hierarchy'!A:A,'Product Hierarchy'!E:E) -> Drywall Hand Tools | F14: =_xlfn.XLOOKUP(B14,'Product Hierarchy'!A:A,'Product Hierarchy'!F:F) -> Taping Knives | G14: 20.99 | H14: 18.89 | I14: 13.22 | J14: Each | K14: 4 | L14: 24 | N14: =M14*I14 -> 0
A15: 450020 | B15: DXTT-2-128 | C15: DEWALT 14"BS Taping Knife-Sft Grp Hndl | D15: =_xlfn.XLOOKUP(B15,'Product Hierarchy'!A:A,'Product Hierarchy'!C:C) -> DEWALT | E15: =_xlfn.XLOOKUP(B15,'Product Hierarchy'!A:A,'Product Hierarchy'!E:E) -> Drywall Hand Tools | F15: =_xlfn.XLOOKUP(B15,'Product Hierarchy'!A:A,'Product Hierarchy'!F:F) -> Taping Knives | G15: 21.99 | H15: 19.79 | I15: 13.85 | J15: Each | K15: 4 | L15: 24 | N15: =M15*I15 -> 0
A16: 450021 | B16: DXTT-2-134 | C16: DEWALT 8"SS Taping Knife-Sft Grp Hndl | D16: =_xlfn.XLOOKUP(B16,'Product Hierarchy'!A:A,'Product Hierarchy'!C:C) -> DEWALT | E16: =_xlfn.XLOOKUP(B16,'Product Hierarchy'!A:A,'Product Hierarchy'!E:E) -> Drywall Hand Tools | F16: =_xlfn.XLOOKUP(B16,'Product Hierarchy'!A:A,'Product Hierarchy'!F:F) -> Taping Knives | G16: 18.49 | H16: 16.64 | I16: 11.65 | J16: Each | K16: 4 | L16: 24 | N16: =M16*I16 -> 0
A17: 450022 | B17: DXTT-2-136 | C17: DEWALT 10"SS Taping Knife-Sft Grp Hndl | D17: =_xlfn.XLOOKUP(B17,'Product Hierarchy'!A:A,'Product Hierarchy'!C:C) -> DEWALT | E17: =_xlfn.XLOOKUP(B17,'Product Hierarchy'!A:A,'Product Hierarchy'!E:E) -> Drywall Hand Tools | F17: =_xlfn.XLOOKUP(B17,'Product Hierarchy'!A:A,'Product Hierarchy'!F:F) -> Taping Knives | G17: 19.49 | H17: 17.54 | I17: 12.28 | J17: Each | K17: 4 | L17: 24 | N17: =M17*I17 -> 0
A18: 450023 | B18: DXTT-2-137 | C18: DEWALT 12"SS Taping Knife-Sft Grp Hndl | D18: =_xlfn.XLOOKUP(B18,'Product Hierarchy'!A:A,'Product Hierarchy'!C:C) -> DEWALT | E18: =_xlfn.XLOOKUP(B18,'Product Hierarchy'!A:A,'Product Hierarchy'!E:E) -> Drywall Hand Tools | F18: =_xlfn.XLOOKUP(B18,'Product Hierarchy'!A:A,'Product Hierarchy'!F:F) -> Taping Knives | G18: 20.99 | H18: 18.89 | I18: 13.22 | J18: Each | K18: 4 | L18: 24 | N18: =M18*I18 -> 0
A19: 450024 | B19: DXTT-2-138 | C19: DEWALT 14"SS Taping Knife-Sft Grp Hndl | D19: =_xlfn.XLOOKUP(B19,'Product Hierarchy'!A:A,'Product Hierarchy'!C:C) -> DEWALT | E19: =_xlfn.XLOOKUP(B19,'Product Hierarchy'!A:A,'Product Hierarchy'!E:E) -> Drywall Hand Tools | F19: =_xlfn.XLOOKUP(B19,'Product Hierarchy'!A:A,'Product Hierarchy'!F:F) -> Taping Knives | G19: 21.99 | H19: 19.79 | I19: 13.85 | J19: Each | K19: 4 | L19: 24 | N19: =M19*I19 -> 0
A20: 450025 | B20: DXTT-2-139 | C20: DEWALT 3"SS Joint Knife-Sft Grp Hndl | D20: =_xlfn.XLOOKUP(B20,'Product Hierarchy'!A:A,'Product Hierarchy'!C:C) -> DEWALT | E20: =_xlfn.XLOOKUP(B20,'Product Hierarchy'!A:A,'Product Hierarchy'!E:E) -> Drywall Hand Tools | F20: =_xlfn.XLOOKUP(B20,'Product Hierarchy'!A:A,'Product Hierarchy'!F:F) -> Joint Knives | G20: 15.49 | H20: 13.94 | I20: 9.76 | J20: Each | K20: 8 | L20: 48 | N20: =M20*I20 -> 0
A21: 450026 | B21: DXTT-2-140 | C21: DEWALT 4"SS Joint Knife-Sft Grp Hndl | D21: =_xlfn.XLOOKUP(B21,'Product Hierarchy'!A:A,'Product Hierarchy'!C:C) -> DEWALT | E21: =_xlfn.XLOOKUP(B21,'Product Hierarchy'!A:A,'Product Hierarchy'!E:E) -> Drywall Hand Tools | F21: =_xlfn.XLOOKUP(B21,'Product Hierarchy'!A:A,'Product Hierarchy'!F:F) -> Joint Knives | G21: 16.49 | H21: 14.84 | I21: 10.39 | J21: Each | K21: 8 | L21: 48 | N21: =M21*I21 -> 0
A22: 450029 | B22: DXTT-2-144 | C22: DEWALT 8"SS Joint Knife-Sft Grp Hndl | D22: =_xlfn.XLOOKUP(B22,'Product Hierarchy'!A:A,'Product Hierarchy'!C:C) -> DEWALT | E22: =_xlfn.XLOOKUP(B22,'Product Hierarchy'!A:A,'Product Hierarchy'!E:E) -> Drywall Hand Tools | F22: =_xlfn.XLOOKUP(B22,'Product Hierarchy'!A:A,'Product Hierarchy'!F:F) -> Joint Knives | G22: 20.99 | H22: 18.89 | I22: 13.22 | J22: Each | K22: 8 | L22: 48 | N22: =M22*I22 -> 0
... A44: 450057 | B44: DXTT-2-202 | C44: DEWALT SS Pointed Knife -Sft Grp Hndl | D44: =_xlfn.XLOOKUP(B44,'Product Hierarchy'!A:A,'Product Hierarchy'!C:C) -> DEWALT | E44: =_xlfn.XLOOKUP(B44,'Product Hierarchy'!A:A,'Product Hierarchy'!E:E) -> Drywall Hand Tools | F44: =_xlfn.XLOOKUP(B44,'Product Hierarchy'!A:A,'Product Hierarchy'!F:F) -> Specialty Knives | G44: 15.99 | H44: 14.39 | I44: 10.07 | J44: Each | K44: 8 | L44: 48 | N44: =M44*I44 -> 0
A45: 450058 | B45: DXTT-2-203 | C45: DEWALT 4" Trim Puller - 4-In-1 Multi Tool | D45: DEWALT | E45: Drywall Hand Tools | F45: Trim Puller | G45: 21.99 | H45: 17.99 | I45: 12.59 | J45: Each | K45: 4 | L45: 40 | N45: =M45*I45 -> 0
A46: 450059 | B46: DXTT-2-291 | C46: DEWALT Mixer 5" Head 32" Shaft | D46: =_xlfn.XLOOKUP(B46,'Product Hierarchy'!A:A,'Product Hierarchy'!C:C) -> DEWALT | E46: =_xlfn.XLOOKUP(B46,'Product Hierarchy'!A:A,'Product Hierarchy'!E:E) -> Drywall Hand Tools | F46: =_xlfn.XLOOKUP(B46,'Product Hierarchy'!A:A,'Product Hierarchy'!F:F) -> Mixers | G46: 36.49 | H46: 32.84 | I46: 22.99 | J46: Each | K46: 4 | L46: 4 | N46: =M46*I46 -> 0
A47: 450060 | B47: DXTT-2-292 | C47: DEWALT Mixer 7" Head 32" Shaft | D47: =_xlfn.XLOOKUP(B47,'Product Hierarchy'!A:A,'Product Hierarchy'!C:C) -> DEWALT | E47: =_xlfn.XLOOKUP(B47,'Product Hierarchy'!A:A,'Product Hierarchy'!E:E) -> Drywall Hand Tools | F47: =_xlfn.XLOOKUP(B47,'Product Hierarchy'!A:A,'Product Hierarchy'!F:F) -> Mixers | G47: 45.49 | H47: 40.94 | I47: 28.66 | J47: Each | K47: 2 | L47: 2 | N47: =M47*I47 -> 0
A48: 450061 | B48: DXTT-2-293 | C48: DEWALT Mixer 2" Head 13" Shaft | D48: =_xlfn.XLOOKUP(B48,'Product Hierarchy'!A:A,'Product Hierarchy'!C:C) -> DEWALT | E48: =_xlfn.XLOOKUP(B48,'Product Hierarchy'!A:A,'Product Hierarchy'!E:E) -> Drywall Hand Tools | F48: =_xlfn.XLOOKUP(B48,'Product Hierarchy'!A:A,'Product Hierarchy'!F:F) -> Mixers | G48: 15.99 | H48: 14.39 | I48: 10.07 | J48: Each | K48: 16 | L48: 16 | N48: =M48*I48 -> 0
A49: 450062 | B49: DXTT-2-294 | C49: DEWALT Mixer 4" Head 28" Shaft | D49: =_xlfn.XLOOKUP(B49,'Product Hierarchy'!A:A,'Product Hierarchy'!C:C) -> DEWALT | E49: =_xlfn.XLOOKUP(B49,'Product Hierarchy'!A:A,'Product Hierarchy'!E:E) -> Drywall Hand Tools | F49: =_xlfn.XLOOKUP(B49,'Product Hierarchy'!A:A,'Product Hierarchy'!F:F) -> Mixers | G49: 30.49 | H49: 27.44 | I49: 19.21 | J49: Each | K49: 8 | L49: 8 | N49: =M49*I49 -> 0
A50: 450063 | B50: DXTT-2-295 | C50: DEWALT Mixer Adaptor-w/HexKey | D50: =_xlfn.XLOOKUP(B50,'Product Hierarchy'!A:A,'Product Hierarchy'!C:C) -> DEWALT | E50: =_xlfn.XLOOKUP(B50,'Product Hierarchy'!A:A,'Product Hierarchy'!E:E) -> Drywall Hand Tools | F50: =_xlfn.XLOOKUP(B50,'Product Hierarchy'!A:A,'Product Hierarchy'!F:F) -> Mixers | G50: 13.49 | H50: 12.14 | I50: 8.5 | J50: Each | K50: 1 | L50: 40 | N50: =M50*I50 -> 0
A51: 450064 | B51: DXTT-2-302 | C51: DEWALT 48" HD Drywall T-Square | D51: =_xlfn.XLOOKUP(B51,'Product Hierarchy'!A:A,'Product Hierarchy'!C:C) -> DEWALT | E51: =_xlfn.XLOOKUP(B51,'Product Hierarchy'!A:A,'Product Hierarchy'!E:E) -> Drywall Hand Tools | F51: =_xlfn.XLOOKUP(B51,'Product Hierarchy'!A:A,'Product Hierarchy'!F:F) -> T-Square | G51: 32.49 | H51: 29.24 | I51: 20.47 | J51: Each | K51: 1 | L51: 4 | N51: =M51*I51 -> 0
A52: 450065 | B52: DXTT-2-305 | C52: DEWALT Pro Texture Sprayer with Hopper | D52: =_xlfn.XLOOKUP(B52,'Product Hierarchy'!A:A,'Product Hierarchy'!C:C) -> DEWALT | E52: =_xlfn.XLOOKUP(B52,'Product Hierarchy'!A:A,'Product Hierarchy'!E:E) -> Drywall Semi Auto Tools | F52: =_xlfn.XLOOKUP(B52,'Product Hierarchy'!A:A,'Product Hierarchy'!F:F) -> Hopper Gun | G52: 151.49 | H52: 136.34 | I52: 95.44 | J52: Each | K52: 1 | L52: 2 | N52: =M52*I52 -> 0
A53: 450066 | B53: DXTT-2-306 | C53: DEWALT Texture Hopper Gun Nozzles | D53: =_xlfn.XLOOKUP(B53,'Product Hierarchy'!A:A,'Product Hierarchy'!C:C) -> DEWALT | E53: =_xlfn.XLOOKUP(B53,'Product Hierarchy'!A:A,'Product Hierarchy'!E:E) -> Drywall Semi Auto Tools | F53: =_xlfn.XLOOKUP(B53,'Product Hierarchy'!A:A,'Product Hierarchy'!F:F) -> Hopper Gun | G53: 16.49 | H53: 14.84 | I53: 10.39 | J53: Each | K53: 6 | L53: 24 | N53: =M53*I53 -> 0
A54: 450068 | B54: DXTT-2-325 | C54: DEWALT Hawk 13" x 13" | D54: =_xlfn.XLOOKUP(B54,'Product Hierarchy'!A:A,'Product Hierarchy'!C:C) -> DEWALT | E54: =_xlfn.XLOOKUP(B54,'Product Hierarchy'!A:A,'Product Hierarchy'!E:E) -> Drywall Hand Tools | F54: =_xlfn.XLOOKUP(B54,'Product Hierarchy'!A:A,'Product Hierarchy'!F:F) -> Hawks | G54: 52.49 | H54: 47.24 | I54: 33.07 | J54: Each | K54: 4 | L54: 4 | N54: =M54*I54 -> 0
A55: 450069 | B55: DXTT-2-326 | C55: DEWALT Hawk 16" x 16" | D55: =_xlfn.XLOOKUP(B55,'Product Hierarchy'!A:A,'Product Hierarchy'!C:C) -> DEWALT | E55: =_xlfn.XLOOKUP(B55,'Product Hierarchy'!A:A,'Product Hierarchy'!E:E) -> Drywall Hand Tools | F55: =_xlfn.XLOOKUP(B55,'Product Hierarchy'!A:A,'Product Hierarchy'!F:F) -> Hawks | G55: 63.99 | H55: 57.59 | I55: 40.31 | J55: Each | K55: 1 | L55: 4 | N55: =M55*I55 -> 0
A56: 450326 | B56: DXTT-7-332 | C56: DEWALT 12"SS Mud Pan | D56: =_xlfn.XLOOKUP(B56,'Product Hierarchy'!A:A,'Product Hierarchy'!C:C) -> DEWALT | E56: =_xlfn.XLOOKUP(B56,'Product Hierarchy'!A:A,'Product Hierarchy'!E:E) -> Drywall Hand Tools | F56: =_xlfn.XLOOKUP(B56,'Product Hierarchy'!A:A,'Product Hierarchy'!F:F) -> Mud Pans | G56: 26.49 | H56: 23.84 | I56: 16.69 | J56: Each | K56: 6 | L56: 12 | N56: =M56*I56 -> 0
A57: 450071 | B57: DXTT-2-334 | C57: DEWALT 14"SS Mud Pan | D57: =_xlfn.XLOOKUP(B57,'Product Hierarchy'!A:A,'Product Hierarchy'!C:C) -> DEWALT | E57: =_xlfn.XLOOKUP(B57,'Product Hierarchy'!A:A,'Product Hierarchy'!E:E) -> Drywall Hand Tools | F57: =_xlfn.XLOOKUP(B57,'Product Hierarchy'!A:A,'Product Hierarchy'!F:F) -> Mud Pans | G57: 27.99 | H57: 25.19 | I57: 17.63 | J57: Each | K57: 6 | L57: 12 | N57: =M57*I57 -> 0
... A84: 450098 | B84: DXTT-2-411 | C84: DEWALT Welded Joint Knife Grips 5Pk | D84: =_xlfn.XLOOKUP(B84,'Product Hierarchy'!A:A,'Product Hierarchy'!C:C) -> DEWALT | E84: =_xlfn.XLOOKUP(B84,'Product Hierarchy'!A:A,'Product Hierarchy'!E:E) -> Drywall Hand Tools | F84: =_xlfn.XLOOKUP(B84,'Product Hierarchy'!A:A,'Product Hierarchy'!F:F) -> Joint Knives | G84: 8.99 | H84: 8.09 | I84: 5.66 | J84: Each | K84: 24 | L84: 144 | N84: =M84*I84 -> 0
A85: 450099 | B85: DXTT-2-414 | C85: DW 8" SS TAPING KNIFE - W/WELDED HNDL | D85: DEWALT | E85: Drywall Hand Tools | F85: Taping Knives | G85: 20.99 | H85: 18.89 | I85: 13.22 | J85: Each | K85: 4 | L85: 24 | N85: =M85*I85 -> 0
A86: 450100 | B86: DXTT-2-416 | C86: DW 10" SS TAPING KNIFE - W/WELDED HNDL | D86: DEWALT | E86: Drywall Hand Tools | F86: Taping Knives | G86: 21.99 | H86: 19.79 | I86: 13.85 | J86: Each | K86: 4 | L86: 24 | N86: =M86*I86 -> 0
A87: 450101 | B87: DXTT-2-417 | C87: DW 12" SS TAPING KNIFE - W/WELDED HNDL | D87: DEWALT | E87: Drywall Hand Tools | F87: Taping Knives | G87: 22.99 | H87: 20.69 | I87: 14.48 | J87: Each | K87: 4 | L87: 24 | N87: =M87*I87 -> 0
A88: 450102 | B88: DXTT-2-418 | C88: DW 14" SS TAPING KNIFE - W/WELDED HNDL | D88: DEWALT | E88: Drywall Hand Tools | F88: Taping Knives | G88: 23.99 | H88: 21.59 | I88: 15.11 | J88: Each | K88: 4 | L88: 24 | N88: =M88*I88 -> 0
A89: 450103 | B89: DXTT-2-420 | C89: DEWALT 4" SS Stretch Joint Knife | D89: =_xlfn.XLOOKUP(B89,'Product Hierarchy'!A:A,'Product Hierarchy'!C:C) -> DEWALT | E89: =_xlfn.XLOOKUP(B89,'Product Hierarchy'!A:A,'Product Hierarchy'!E:E) -> Drywall Hand Tools | F89: =_xlfn.XLOOKUP(B89,'Product Hierarchy'!A:A,'Product Hierarchy'!F:F) -> Joint Knives | G89: 25.99 | H89: 23.39 | I89: 16.37 | J89: Each | K89: 8 | L89: 48 | N89: =M89*I89 -> 0
A90: 450104 | B90: DXTT-2-421 | C90: DEWALT 5" SS Stretch Joint Knife | D90: =_xlfn.XLOOKUP(B90,'Product Hierarchy'!A:A,'Product Hierarchy'!C:C) -> DEWALT | E90: =_xlfn.XLOOKUP(B90,'Product Hierarchy'!A:A,'Product Hierarchy'!E:E) -> Drywall Hand Tools | F90: =_xlfn.XLOOKUP(B90,'Product Hierarchy'!A:A,'Product Hierarchy'!F:F) -> Joint Knives | G90: 26.99 | H90: 24.29 | I90: 17 | J90: Each | K90: 8 | L90: 48 | N90: =M90*I90 -> 0
...

Sheet Order Input-Individual Part 
F1: Order Form
A3: Customer: | C3: ='Order Summary'!B3 -> 0 | J3: Order date: | L3: ='Order Summary'!F3 -> 0
A4: Ship To: | C4: ='Order Summary'!B4 -> 0 | J4: PO#: | L4: ='Order Summary'!F4 -> 0
A5: ='Order Summary'!B5 -> 0 | J5: Need by date: | L5: ='Order Summary'!F5 -> 0
A6: ='Order Summary'!B6 -> 0 | J6: Carrier: | L6: ='Order Summary'!F6 -> 0
A7: ALL PARTS SALES ARE FINAL
A8: Part # | B8: Sku # | C8: Description | D8: Brand | E8: Product Group | F8: Product Type | G8: MSRP | H8: MAPP | I8: Your Price | J8: UOM | K8: Order Quantity | L8: Total Price
A9: TAPER PARTS
A10: 449209 | B10: 7001 | C10: Handle Outlet Valve | D10: LEVEL5 | E10: Drywall Auto Tools | F10: Parts | G10: 37.99 | H10: 32.29 | I10: 22.6 | J10: Each | L10: =K10*I10 -> 0
A11: 449210 | B11: 7002 | C11: Wiper, Control Valve | D11: LEVEL5 | E11: Drywall Auto Tools | F11: Parts | G11: 5.49 | H11: 4.67 | I11: 3.27 | J11: Each | L11: =K11*I11 -> 0
A12: 448572 | B12: 7005 | C12: Lock Roller Assembly (Brake) | D12: LEVEL5 | E12: Drywall Auto Tools | F12: Parts | G12: 15.49 | H12: 13.17 | I12: 9.22 | J12: Each | L12: =K12*I12 -> 0
A13: 448579 | B13: 7035 | C13: Anvil | D13: LEVEL5 | E13: Drywall Auto Tools | F13: Parts | G13: 18.49 | H13: 15.72 | I13: 11 | J13: Each | L13: =K13*I13 -> 0
A14: 448583 | B14: 7040 | C14: Needle Gooser | D14: LEVEL5 | E14: Drywall Auto Tools | F14: Parts | G14: 1.99 | H14: 1.69 | I14: 1.18 | J14: Each | L14: =K14*I14 -> 0
A15: 448589 | B15: 7059 | C15: Creaser Wheel | D15: LEVEL5 | E15: Drywall Auto Tools | F15: Parts | G15: 5.99 | H15: 5.09 | I15: 3.56 | J15: Each | L15: =K15*I15 -> 0
A16: 448438 | B16: 7063 | C16: Bearing Nyliner | D16: LEVEL5 | E16: Drywall Auto Tools | F16: Parts | G16: 2.49 | H16: 2.12 | I16: 1.48 | J16: Each | L16: =K16*I16 -> 0
A17: 448956 | B17: 7069 | C17: 8-32 x 5/16 Setscrew | D17: LEVEL5 | E17: Drywall Auto Tools | F17: Parts | G17: 3.99 | H17: 3.39 | I17: 2.37 | J17: Each | L17: =K17*I17 -> 0
A18: 448593 | B18: 7077 | C18: Taper Wheel | D18: LEVEL5 | E18: Drywall Auto Tools | F18: Parts | G18: 21.49 | H18: 18.27 | I18: 12.79 | J18: Each | L18: =K18*I18 -> 0
A19: 448966 | B19: 7094 | C19: Spring Drive Dog | D19: LEVEL5 | E19: Drywall Auto Tools | F19: Parts | G19: 3.49 | H19: 2.97 | I19: 2.08 | J19: Each | L19: =K19*I19 -> 0
A20: 448605 | B20: 7097 | C20: Drive Dog Assembly | D20: LEVEL5 | E20: Drywall Auto Tools | F20: Parts | G20: 150.49 | H20: 127.92 | I20: 89.54 | J20: Each | L20: =K20*I20 -> 0
A21: 448494 | B21: 7104 | C21: Main Chain | D21: LEVEL5 | E21: Drywall Auto Tools | F21: Parts | G21: 75.49 | H21: 64.17 | I21: 44.92 | J21: Each | L21: =K21*I21 -> 0
... A38: 449124 | B38: 9108 | C38: Cutter Spring- Taper | D38: LEVEL5 | E38: Drywall Auto Tools | F38: Parts | G38: 18.49 | H38: 15.72 | I38: 11 | J38: Each | L38: =K38*I38 -> 0
A39: PUMP PARTS
A40: 448670 | B40: 7323 | C40: Gland | D40: LEVEL5 | E40: Drywall Auto Tools | F40: Parts | G40: 36.49 | H40: 31.02 | I40: 21.71 | J40: Each | L40: =K40*I40 -> 0
A41: 449187 | B41: 7324 | C41: U-Seal | D41: LEVEL5 | E41: Drywall Auto Tools | F41: Parts | G41: 4.99 | H41: 4.24 | I41: 2.97 | J41: Each | L41: =K41*I41 -> 0
A42: 449022 | B42: 7326 | C42: 5/16-24 Hex Head | D42: LEVEL5 | E42: Drywall Auto Tools | F42: Parts | G42: 1.99 | H42: 1.69 | I42: 1.18 | J42: Each | L42: =K42*I42 -> 0
A43: 449024 | B43: 7328 | C43: Piston Cups | D43: LEVEL5 | E43: Drywall Auto Tools | F43: Parts | G43: 13.99 | H43: 11.89 | I43: 8.32 | J43: Each | L43: =K43*I43 -> 0
A44: 448671 | B44: 7329 | C44: Valve Disc | D44: LEVEL5 | E44: Drywall Auto Tools | F44: Parts | G44: 9.49 | H44: 8.07 | I44: 5.65 | J44: Each | L44: =K44*I44 -> 0
A45: 449177 | B45: 7350 | C45: Filler O'Ring | D45: LEVEL5 | E45: Drywall Auto Tools | F45: Parts | G45: 1.99 | H45: 1.69 | I45: 1.18 | J45: Each | L45: =K45*I45 -> 0
A46: 449029 | B46: 7352 | C46: 5-16-24 x 1 7/16 Std Screw | D46: LEVEL5 | E46: Drywall Auto Tools | F46: Parts | G46: 12.49 | H46: 10.62 | I46: 7.43 | J46: Each | L46: =K46*I46 -> 0
A47: 449030 | B47: 7353 | C47: Special Nut | D47: LEVEL5 | E47: Drywall Auto Tools | F47: Parts | G47: 12.49 | H47: 10.62 | I47: 7.43 | J47: Each | L47: =K47*I47 -> 0
A48: 448675 | B48: 7355 | C48: Filler Body | D48: LEVEL5 | E48: Drywall Auto Tools | F48: Parts | G48: 60.49 | H48: 51.42 | I48: 35.99 | J48: Each | L48: =K48*I48 -> 0
A49: 448676 | B49: 7356 | C49: Discharge Tube | D49: LEVEL5 | E49: Drywall Auto Tools | F49: Parts | G49: 30.49 | H49: 25.92 | I49: 18.14 | J49: Each | L49: =K49*I49 -> 0
A50: 448677 | B50: 7358 | C50: Chain Assembly (W/ 1 S Hook) | D50: LEVEL5 | E50: Drywall Auto Tools | F50: Parts | G50: 22.49 | H50: 19.12 | I50: 13.38 | J50: Each | L50: =K50*I50 -> 0
A51: 449188 | B51: 7362 | C51: Gooseneck Gasket | D51: LEVEL5 | E51: Drywall Auto Tools | F51: Parts | G51: 6.49 | H51: 5.52 | I51: 3.86 | J51: Each | L51: =K51*I51 -> 0
... A58: 448887 | B58: 9624 | C58: Pump Tube | D58: LEVEL5 | E58: Drywall Auto Tools | F58: Parts | G58: 180.49 | H58: 153.42 | I58: 107.39 | J58: Each | L58: =K58*I58 -> 0
A59: BOX PARTS
A60: 448441 | B60: 7119 | C60: Nylon Bearing-Straight | D60: LEVEL5 | E60: Drywall Auto Tools | F60: Parts | G60: 4.49 | H60: 3.82 | I60: 2.67 | J60: Each | L60: =K60*I60 -> 0
A61: 448634 | B61: 7207 | C61: 7" Flat Box Blade | D61: LEVEL5 | E61: Drywall Auto Tools | F61: Parts | G61: 4.99 | H61: 4.24 | I61: 2.97 | J61: Each | L61: =K61*I61 -> 0
A62: 448635 | B62: 7208 | C62: Blade Holder Assembly 7" | D62: LEVEL5 | E62: Drywall Auto Tools | F62: Parts | G62: 180.49 | H62: 153.42 | I62: 107.39 | J62: Each | L62: =K62*I62 -> 0
A63: 448636 | B63: 7212 | C63: Skid Cover Rt Side, Universal | D63: LEVEL5 | E63: Drywall Auto Tools | F63: Parts | G63: 3.49 | H63: 2.97 | I63: 2.08 | J63: Each | L63: =K63*I63 -> 0
...

Sheet Order Input-Part Kits
F1: Order Form
A3: Customer: | C3: ='Order Summary'!B3 -> 0 | J3: Order date: | L3: ='Order Summary'!F3 -> 0
A4: Ship To: | C4: ='Order Summary'!B4 -> 0 | J4: PO#: | L4: ='Order Summary'!F4 -> 0
A5: ='Order Summary'!B5 -> 0 | J5: Need by date: | L5: ='Order Summary'!F5 -> 0
A6: ='Order Summary'!B6 -> 0 | J6: Carrier: | L6: ='Order Summary'!F6 -> 0
A7: ALL PARTS SALES ARE FINAL
A8: Part # | B8: Sku # | C8: Description | D8: Brand | E8: Product Group | F8: Product Type | G8: MSRP | H8: MAPP | I8: Your Price | J8: UOM | K8: Order Quantity | L8: Total Price
A9: 449578 | B9: 4-800 | C9: Pump Repair Kit | D9: =_xlfn.XLOOKUP(B9,'Product Hierarchy'!A:A,'Product Hierarchy'!C:C) -> LEVEL5 | E9: =_xlfn.XLOOKUP(B9,'Product Hierarchy'!A:A,'Product Hierarchy'!E:E) -> Drywall Auto Tools | F9: =_xlfn.XLOOKUP(B9,'Product Hierarchy'!A:A,'Product Hierarchy'!F:F) -> Repair Kits | G9: 45.92 | H9: 36.74 | I9: 25.72 | J9: Each | L9: =K9*I9 -> 0
A10: 449579 | B10: 4-801 | C10: Pump Rebuild Kit | D10: =_xlfn.XLOOKUP(B10,'Product Hierarchy'!A:A,'Product Hierarchy'!C:C) -> LEVEL5 | E10: =_xlfn.XLOOKUP(B10,'Product Hierarchy'!A:A,'Product Hierarchy'!E:E) -> Drywall Auto Tools | F10: =_xlfn.XLOOKUP(B10,'Product Hierarchy'!A:A,'Product Hierarchy'!F:F) -> Repair Kits | G10: 41.45 | H10: 33.16 | I10: 23.21 | J10: Each | L10: =K10*I10 -> 0
A11: 448546 | B11: 4-802 | C11: Ext. Box Handle Brake Assembly | D11: =_xlfn.XLOOKUP(B11,'Product Hierarchy'!A:A,'Product Hierarchy'!C:C) -> LEVEL5 | E11: =_xlfn.XLOOKUP(B11,'Product Hierarchy'!A:A,'Product Hierarchy'!E:E) -> Drywall Auto Tools | F11: =_xlfn.XLOOKUP(B11,'Product Hierarchy'!A:A,'Product Hierarchy'!F:F) -> Parts | G11: 44.46 | H11: 37.79 | I11: 26.45 | J11: Each | L11: =K11*I11 -> 0
A12: 449580 | B12: 4-803 | C12: Cleaning Kit | D12: =_xlfn.XLOOKUP(B12,'Product Hierarchy'!A:A,'Product Hierarchy'!C:C) -> LEVEL5 | E12: =_xlfn.XLOOKUP(B12,'Product Hierarchy'!A:A,'Product Hierarchy'!E:E) -> Drywall Auto Tools | F12: =_xlfn.XLOOKUP(B12,'Product Hierarchy'!A:A,'Product Hierarchy'!F:F) -> Repair Kits | G12: 99.46 | H12: 79.57 | I12: 55.7 | J12: Each | L12: =K12*I12 -> 0
A13: 449581 | B13: 4-805 | C13: 7" Flat Box Seal | D13: =_xlfn.XLOOKUP(B13,'Product Hierarchy'!A:A,'Product Hierarchy'!C:C) -> LEVEL5 | E13: =_xlfn.XLOOKUP(B13,'Product Hierarchy'!A:A,'Product Hierarchy'!E:E) -> Drywall Auto Tools | F13: =_xlfn.XLOOKUP(B13,'Product Hierarchy'!A:A,'Product Hierarchy'!F:F) -> Repair Kits | G13: 42.49 | H13: 33.99 | I13: 23.79 | J13: Each | L13: =K13*I13 -> 0
A14: 449184 | B14: 4-806 | C14: 10" Flat Box Seal | D14: =_xlfn.XLOOKUP(B14,'Product Hierarchy'!A:A,'Product Hierarchy'!C:C) -> LEVEL5 | E14: =_xlfn.XLOOKUP(B14,'Product Hierarchy'!A:A,'Product Hierarchy'!E:E) -> Drywall Auto Tools | F14: =_xlfn.XLOOKUP(B14,'Product Hierarchy'!A:A,'Product Hierarchy'!F:F) -> Parts | G14: 52.99 | H14: 45.04 | I14: 31.53 | J14: Each | L14: =K14*I14 -> 0
A15: 449582 | B15: 4-807 | C15: 12" Flat Box Seal | D15: =_xlfn.XLOOKUP(B15,'Product Hierarchy'!A:A,'Product Hierarchy'!C:C) -> LEVEL5 | E15: =_xlfn.XLOOKUP(B15,'Product Hierarchy'!A:A,'Product Hierarchy'!E:E) -> Drywall Auto Tools | F15: =_xlfn.XLOOKUP(B15,'Product Hierarchy'!A:A,'Product Hierarchy'!F:F) -> Repair Kits | G15: 60.49 | H15: 48.39 | I15: 33.87 | J15: Each | L15: =K15*I15 -> 0
A16: 449583 | B16: 4-808 | C16: Flat Box Repair Kit | D16: =_xlfn.XLOOKUP(B16,'Product Hierarchy'!A:A,'Product Hierarchy'!C:C) -> LEVEL5 | E16: =_xlfn.XLOOKUP(B16,'Product Hierarchy'!A:A,'Product Hierarchy'!E:E) -> Drywall Auto Tools | F16: =_xlfn.XLOOKUP(B16,'Product Hierarchy'!A:A,'Product Hierarchy'!F:F) -> Repair Kits | G16: 58.9 | H16: 47.12 | I16: 32.98 | J16: Each | L16: =K16*I16 -> 0
A17: 448547 | B17: 4-811 | C17: Cleaning Nozzles 2pk | D17: =_xlfn.XLOOKUP(B17,'Product Hierarchy'!A:A,'Product Hierarchy'!C:C) -> LEVEL5 | E17: =_xlfn.XLOOKUP(B17,'Product Hierarchy'!A:A,'Product Hierarchy'!E:E) -> Drywall Auto Tools | F17: =_xlfn.XLOOKUP(B17,'Product Hierarchy'!A:A,'Product Hierarchy'!F:F) -> Parts | G17: 27.98 | H17: 23.78 | I17: 16.65 | J17: Each | L17: =K17*I17 -> 0
A18: 448548 | B18: 4-812 | C18: Tape Jam Remover | D18: =_xlfn.XLOOKUP(B18,'Product Hierarchy'!A:A,'Product Hierarchy'!C:C) -> LEVEL5 | E18: =_xlfn.XLOOKUP(B18,'Product Hierarchy'!A:A,'Product Hierarchy'!E:E) -> Drywall Auto Tools | F18: =_xlfn.XLOOKUP(B18,'Product Hierarchy'!A:A,'Product Hierarchy'!F:F) -> Parts | G18: 18.49 | H18: 15.72 | I18: 11 | J18: Each | L18: =K18*I18 -> 0
A19: 448549 | B19: 4-813 | C19: Gooseneck Brush | D19: =_xlfn.XLOOKUP(B19,'Product Hierarchy'!A:A,'Product Hierarchy'!C:C) -> LEVEL5 | E19: =_xlfn.XLOOKUP(B19,'Product Hierarchy'!A:A,'Product Hierarchy'!E:E) -> Drywall Auto Tools | F19: =_xlfn.XLOOKUP(B19,'Product Hierarchy'!A:A,'Product Hierarchy'!F:F) -> Parts | G19: 52.99 | H19: 45.04 | I19: 31.53 | J19: Each | L19: =K19*I19 -> 0
A20: 449584 | B20: 4-815 | C20: Taper Repair Kit | D20: =_xlfn.XLOOKUP(B20,'Product Hierarchy'!A:A,'Product Hierarchy'!C:C) -> LEVEL5 | E20: =_xlfn.XLOOKUP(B20,'Product Hierarchy'!A:A,'Product Hierarchy'!E:E) -> Drywall Auto Tools | F20: =_xlfn.XLOOKUP(B20,'Product Hierarchy'!A:A,'Product Hierarchy'!F:F) -> Repair Kits | G20: 91.31 | H20: 73.05 | I20: 51.14 | J20: Each | L20: =K20*I20 -> 0
... A73: 449205 | B73: DXTT-2-807 | C73: DW 12"Flat Box Seal | D73: =_xlfn.XLOOKUP(B73,'Product Hierarchy'!A:A,'Product Hierarchy'!C:C) -> DEWALT | E73: =_xlfn.XLOOKUP(B73,'Product Hierarchy'!A:A,'Product Hierarchy'!E:E) -> Drywall Auto Tools | F73: =_xlfn.XLOOKUP(B73,'Product Hierarchy'!A:A,'Product Hierarchy'!F:F) -> Parts | G73: 60.49 | H73: 48.39 | I73: 33.87 | J73: Each | L73: =K73*I73 -> 0
J74: Total | K74: =SUM(K10:K73) -> 0 | L74: =SUM(L10:L73) -> 0

Sheet Order Input-Merch. And Mktg
F1: Order Form
A3: Customer: | B3: ='Order Summary'!B3 -> 0 | I3: Order date: | K3: ='Order Summary'!F3 -> 0
A4: Ship To: | B4: ='Order Summary'!B4 -> 0 | I4: PO#: | K4: ='Order Summary'!F4 -> 0
A5: ='Order Summary'!B5 -> 0 | I5: Need by date: | K5: ='Order Summary'!F5 -> 0
A6: ='Order Summary'!B6 -> 0 | I6: Carrier: | K6: ='Order Summary'!F6 -> 0
A7: ALL MERCH & MKTG SALES ARE FINAL
A8: Part # | B8: Sku # | C8: Description | D8: Brand | E8: Product Group | F8: Product Type | G8: MSRP | H8: MAPP | I8: Your Price | J8: UOM | K8: Order Quantity | L8: Total Price
A9: 449220 | B9: 1-120 | C9: L5T Baseball Cap | D9: =_xlfn.XLOOKUP(B9,'Product Hierarchy'!A:A,'Product Hierarchy'!C:C) -> LEVEL5 | E9: =_xlfn.XLOOKUP(B9,'Product Hierarchy'!A:A,'Product Hierarchy'!E:E) -> Misc | F9: =_xlfn.XLOOKUP(B9,'Product Hierarchy'!A:A,'Product Hierarchy'!F:F) -> Clothing | G9: 9.49 | H9: 8.54 | I9: 5.98 | J9: Each | L9: =K9*I9 -> 0
A10: 449239 | B10: 1-301 | C10: Safety Green T-Shirt Version 3 - Small | D10: =_xlfn.XLOOKUP(B10,'Product Hierarchy'!A:A,'Product Hierarchy'!C:C) -> LEVEL5 | E10: =_xlfn.XLOOKUP(B10,'Product Hierarchy'!A:A,'Product Hierarchy'!E:E) -> Misc | F10: =_xlfn.XLOOKUP(B10,'Product Hierarchy'!A:A,'Product Hierarchy'!F:F) -> Clothing | G10: 19.99 | H10: 17.99 | I10: 12.59 | J10: Each | L10: =K10*I10 -> 0
A11: 449240 | B11: 1-302 | C11: Safety Green T-Shirt Version 3 - Medium | D11: =_xlfn.XLOOKUP(B11,'Product Hierarchy'!A:A,'Product Hierarchy'!C:C) -> LEVEL5 | E11: =_xlfn.XLOOKUP(B11,'Product Hierarchy'!A:A,'Product Hierarchy'!E:E) -> Misc | F11: =_xlfn.XLOOKUP(B11,'Product Hierarchy'!A:A,'Product Hierarchy'!F:F) -> Clothing | G11: 19.99 | H11: 17.99 | I11: 12.59 | J11: Each | L11: =K11*I11 -> 0
A12: 449241 | B12: 1-303 | C12: Safety Green T-Shirt Version 3 - Large | D12: =_xlfn.XLOOKUP(B12,'Product Hierarchy'!A:A,'Product Hierarchy'!C:C) -> LEVEL5 | E12: =_xlfn.XLOOKUP(B12,'Product Hierarchy'!A:A,'Product Hierarchy'!E:E) -> Misc | F12: =_xlfn.XLOOKUP(B12,'Product Hierarchy'!A:A,'Product Hierarchy'!F:F) -> Clothing | G12: 19.99 | H12: 17.99 | I12: 12.59 | J12: Each | L12: =K12*I12 -> 0
A13: 449242 | B13: 1-304 | C13: Safety Green T-Shirt Version 3 - XL | D13: =_xlfn.XLOOKUP(B13,'Product Hierarchy'!A:A,'Product Hierarchy'!C:C) -> LEVEL5 | E13: =_xlfn.XLOOKUP(B13,'Product Hierarchy'!A:A,'Product Hierarchy'!E:E) -> Misc | F13: =_xlfn.XLOOKUP(B13,'Product Hierarchy'!A:A,'Product Hierarchy'!F:F) -> Clothing | G13: 19.99 | H13: 17.99 | I13: 12.59 | J13: Each | L13: =K13*I13 -> 0
A14: 449243 | B14: 1-305 | C14: Safety Green T-Shirt Version 3 - 2XL | D14: =_xlfn.XLOOKUP(B14,'Product Hierarchy'!A:A,'Product Hierarchy'!C:C) -> LEVEL5 | E14: =_xlfn.XLOOKUP(B14,'Product Hierarchy'!A:A,'Product Hierarchy'!E:E) -> Misc | F14: =_xlfn.XLOOKUP(B14,'Product Hierarchy'!A:A,'Product Hierarchy'!F:F) -> Clothing | G14: 19.99 | H14: 17.99 | I14: 12.59 | J14: Each | L14: =K14*I14 -> 0
A15: 449244 | B15: 1-306 | C15: Safety Green T-Shirt Version 3 - 3XL | D15: =_xlfn.XLOOKUP(B15,'Product Hierarchy'!A:A,'Product Hierarchy'!C:C) -> LEVEL5 | E15: =_xlfn.XLOOKUP(B15,'Product Hierarchy'!A:A,'Product Hierarchy'!E:E) -> Misc | F15: =_xlfn.XLOOKUP(B15,'Product Hierarchy'!A:A,'Product Hierarchy'!F:F) -> Clothing | G15: 19.99 | H15: 17.99 | I15: 12.59 | J15: Each | L15: =K15*I15 -> 0
A16: 449245 | B16: 1-311 | C16: Red T-Shirt Version 3 - Small | D16: =_xlfn.XLOOKUP(B16,'Product Hierarchy'!A:A,'Product Hierarchy'!C:C) -> LEVEL5 | E16: =_xlfn.XLOOKUP(B16,'Product Hierarchy'!A:A,'Product Hierarchy'!E:E) -> Misc | F16: =_xlfn.XLOOKUP(B16,'Product Hierarchy'!A:A,'Product Hierarchy'!F:F) -> Clothing | G16: 19.99 | H16: 17.99 | I16: 12.59 | J16: Each | L16: =K16*I16 -> 0
A17: 449246 | B17: 1-312 | C17: Red T-Shirt Version 3 - Medium | D17: =_xlfn.XLOOKUP(B17,'Product Hierarchy'!A:A,'Product Hierarchy'!C:C) -> LEVEL5 | E17: =_xlfn.XLOOKUP(B17,'Product Hierarchy'!A:A,'Product Hierarchy'!E:E) -> Misc | F17: =_xlfn.XLOOKUP(B17,'Product Hierarchy'!A:A,'Product Hierarchy'!F:F) -> Clothing | G17: 19.99 | H17: 17.99 | I17: 12.59 | J17: Each | L17: =K17*I17 -> 0
A18: 449247 | B18: 1-313 | C18: Red T-Shirt Version 3 - Large | D18: =_xlfn.XLOOKUP(B18,'Product Hierarchy'!A:A,'Product Hierarchy'!C:C) -> LEVEL5 | E18: =_xlfn.XLOOKUP(B18,'Product Hierarchy'!A:A,'Product Hierarchy'!E:E) -> Misc | F18: =_xlfn.XLOOKUP(B18,'Product Hierarchy'!A:A,'Product Hierarchy'!F:F) -> Clothing | G18: 19.99 | H18: 17.99 | I18: 12.59 | J18: Each | L18: =K18*I18 -> 0
A19: 449248 | B19: 1-314 | C19: Red T-Shirt Version 3 - XL | D19: =_xlfn.XLOOKUP(B19,'Product Hierarchy'!A:A,'Product Hierarchy'!C:C) -> LEVEL5 | E19: =_xlfn.XLOOKUP(B19,'Product Hierarchy'!A:A,'Product Hierarchy'!E:E) -> Misc | F19: =_xlfn.XLOOKUP(B19,'Product Hierarchy'!A:A,'Product Hierarchy'!F:F) -> Clothing | G19: 19.99 | H19: 17.99 | I19: 12.59 | J19: Each | L19: =K19*I19 -> 0
B20: 9-100 | C20: Brochure-DW Hand Tools | D20: =_xlfn.XLOOKUP(B20,'Product Hierarchy'!A:A,'Product Hierarchy'!C:C) -> DEWALT | E20: =_xlfn.XLOOKUP(B20,'Product Hierarchy'!A:A,'Product Hierarchy'!E:E) -> Misc | F20: =_xlfn.XLOOKUP(B20,'Product Hierarchy'!A:A,'Product Hierarchy'!F:F) -> Catalogs | G20: 0 | H20: 0 | I20: 0 | J20: Each | L20: =K20*I20 -> 0
B21: 9-101 | C21: Brochure-DW Automatic Taping Tools | D21: =_xlfn.XLOOKUP(B21,'Product Hierarchy'!A:A,'Product Hierarchy'!C:C) -> DEWALT | E21: =_xlfn.XLOOKUP(B21,'Product Hierarchy'!A:A,'Product Hierarchy'!E:E) -> Misc | F21: =_xlfn.XLOOKUP(B21,'Product Hierarchy'!A:A,'Product Hierarchy'!F:F) -> Catalogs | G21: 0 | H21: 0 | I21: 0 | J21: Each | L21: =K21*I21 -> 0
A22: 450981 | B22: 9-104 | C22: Brochure-L5 Hand Tools | D22: =_xlfn.XLOOKUP(B22,'Product Hierarchy'!A:A,'Product Hierarchy'!C:C) -> LEVEL5 | E22: =_xlfn.XLOOKUP(B22,'Product Hierarchy'!A:A,'Product Hierarchy'!E:E) -> Misc | F22: =_xlfn.XLOOKUP(B22,'Product Hierarchy'!A:A,'Product Hierarchy'!F:F) -> Catalogs | G22: 0 | H22: 0 | I22: 0 | J22: Each | L22: =K22*I22 -> 0
A23: 450982 | B23: 9-105 | C23: Brochure-L5 Automatic Taping Tools | D23: =_xlfn.XLOOKUP(B23,'Product Hierarchy'!A:A,'Product Hierarchy'!C:C) -> LEVEL5 | E23: =_xlfn.XLOOKUP(B23,'Product Hierarchy'!A:A,'Product Hierarchy'!E:E) -> Misc | F23: =_xlfn.XLOOKUP(B23,'Product Hierarchy'!A:A,'Product Hierarchy'!F:F) -> Catalogs | G23: 0 | H23: 0 | I23: 0 | J23: Each | L23: =K23*I23 -> 0
A24: 450983 | B24: 9-106 | C24: Brochure-L5 Skimming Blades | D24: =_xlfn.XLOOKUP(B24,'Product Hierarchy'!A:A,'Product Hierarchy'!C:C) -> LEVEL5 | E24: =_xlfn.XLOOKUP(B24,'Product Hierarchy'!A:A,'Product Hierarchy'!E:E) -> Misc | F24: =_xlfn.XLOOKUP(B24,'Product Hierarchy'!A:A,'Product Hierarchy'!F:F) -> Catalogs | G24: 0 | H24: 0 | I24: 0 | J24: Each | L24: =K24*I24 -> 0
J25: Merchandise and Marketing totals: | K25: =SUM(K9:K24) -> 0 | L25: =SUM(L9:L24) -> 0
